Workbook

Sheet Read Me
A1: Material Price Tracker - How to use this file
A3: WHAT THIS FILE DOES
A4: Every week, you buy materials from one or more locations/suppliers. This file keeps a permanent
A5: history of every price you ever paid, so you can instantly see if a seller quietly raised a price,
A6: and compare prices across locations for the same item.
A8: TABS IN THIS FILE
A10: 1) Data Entry <-- YOU TYPE HERE EVERY WEEK
A11: Add one new row per item you buy. Fill in Date, Location, Supplier, Item Code, Item Name,
A12: Unit, Qty, and Unit Price. 'Amount' calculates itself automatically.
A13: Item Code / Item Name have dropdown suggestions (click the cell, then the small arrow) pulled
A14: from the 'Item List' tab - but you can also just type a brand new one freely; it is optional.
A16: 2) Item List <-- your master catalogue of items
... A58: see how everything works with real numbers. Feel free to edit or delete the seed rows.

Sheet Data Entry
A1: Data Entry - type every purchase here
A2: One row per item you buy. Add new rows at the bottom every time you shop / every week. Item Code & Item Name have dropdown suggestions from 'Item List' - you can also just type a new one.
A4: Date | B4: Location / Site | C4: Supplier / Seller | D4: Item Code | E4: Item Name | F4: Unit | G4: Qty | H4: Unit Price ($) | I4: Amount ($) | J4: Notes
A5: 46204 | B5: Site 1 | C5: Unknown Supplier | D5: G0036 | E5: koh spean khley 25mm2 | F5: graib | G5: 20 | H5: 0.25 | I5: =IF(G5="","",G5*H5) | J5: Week 1 seed data (Jul 1-6, 2026 total)
A6: 46204 | B6: Site 1 | C6: Unknown Supplier | D6: G0044 | E6: koh spean khley 95mm2 | F6: graib | G6: 2 | H6: 0.75 | I6: =IF(G6="","",G6*H6) | J6: Week 1 seed data (Jul 1-6, 2026 total)
A7: 46204 | B7: Site 1 | C7: Unknown Supplier | D7: G0045 | E7: PVC song 3/4 | F7: graib | G7: 3 | H7: 0.5 | I7: =IF(G7="","",G7*H7) | J7: Week 1 seed data (Jul 1-6, 2026 total)
A8: 46204 | B8: Site 1 | C8: Unknown Supplier | D8: G0048 | E8: tuyou PVC 42 (8.5mm) | F8: daeum | G8: 1 | H8: 3 | I8: =IF(G8="","",G8*H8) | J8: Week 1 seed data (Jul 1-6, 2026 total)
A9: 46204 | B9: Site 1 | C9: Unknown Supplier | D9: G0049 | E9: tuyou PVC 21 (13.5mm) | F9: daeum | G9: 7 | H9: 2.4286 | I9: =IF(G9="","",G9*H9) | J9: Week 1 seed data (Jul 1-6, 2026 total)
A10: 46204 | B10: Site 1 | C10: Unknown Supplier | D10: G0050 | E10: PVC song thmenh 42 | F10: graib | G10: 2 | H10: 0.75 | I10: =IF(G10="","",G10*H10) | J10: Week 1 seed data (Jul 1-6, 2026 total)
A11: 46204 | B11: Site 1 | C11: Unknown Supplier | D11: G0051 | E11: PVC song thmenh krao 3/4 | F11: graib | G11: 2 | H11: 0.5 | I11: =IF(G11="","",G11*H11) | J11: Week 1 seed data (Jul 1-6, 2026 total)
A12: 46204 | B12: Site 1 | C12: Unknown Supplier | D12: G0052 | E12: PVC song thmenh knong 3/4 | F12: graib | G12: 2 | H12: 0.5 | I12: =IF(G12="","",G12*H12) | J12: Week 1 seed data (Jul 1-6, 2026 total)
A13: 46204 | B13: Site 1 | C13: Unknown Supplier | D13: G0053 | E13: PVC song thmenh knong 21 | F13: graib | G13: 2 | H13: 0.25 | I13: =IF(G13="","",G13*H13) | J13: Week 1 seed data (Jul 1-6, 2026 total)
A14: 46204 | B14: Site 1 | C14: Unknown Supplier | D14: G0054 | E14: song PVC 42 x 34 | F14: graib | G14: 2 | H14: 0.75 | I14: =IF(G14="","",G14*H14) | J14: Week 1 seed data (Jul 1-6, 2026 total)
A15: 46204 | B15: Site 1 | C15: Unknown Supplier | D15: G0055 | E15: dey mi 42 | F15: graib | G15: 2 | H15: 2.5 | I15: =IF(G15="","",G15*H15) | J15: Week 1 seed data (Jul 1-6, 2026 total)
A16: 46204 | B16: Site 1 | C16: Unknown Supplier | D16: G0056 | E16: kaeng 21 | F16: graib | G16: 11 | H16: 0.25 | I16: =IF(G16="","",G16*H16) | J16: Week 1 seed data (Jul 1-6, 2026 total)
... A45: 46204 | B45: Site 1 | C45: Unknown Supplier | D45: G0083 | E45: koh 50 | F45: graib | G45: 8 | H45: 1 | I45: =IF(G45="","",G45*H45) | J45: Week 1 seed data (Jul 1-6, 2026 total)
I46: =IF(G46="","",G46*H46)
I47: =IF(G47="","",G47*H47)
I48: =IF(G48="","",G48*H48)
I49: =IF(G49="","",G49*H49)
I50: =IF(G50="","",G50*H50)
I51: =IF(G51="","",G51*H51)
I52: =IF(G52="","",G52*H52)
I53: =IF(G53="","",G53*H53)
I54: =IF(G54="","",G54*H54)
I55: =IF(G55="","",G55*H55)
I56: =IF(G56="","",G56*H56)
I57: =IF(G57="","",G57*H57)
... I2001: =IF(G2001="","",G2001*H2001)

Sheet Item Lookup
A1: Item Lookup - search one item
A2: Type or pick an Item Code (or Item Name) in the yellow box below. Everything else updates automatically.
A4: Search by Item Code or Name: | C4: G0075
A6: Item Name: | C6: =IFERROR(INDEX('Item List'!$B$5:$B$500,MATCH('Item Lookup'!$C$4,'Item List'!$A$5:$A$500,0)),IF(COUNTIF('Item List'!$B$5:$B$500,'Item Lookup'!$C$4)>0,'Item Lookup'!$C$4,"(not found in Item List - showing history only)"))
A7: Unit: | C7: =IFERROR(INDEX('Item List'!$C$5:$C$500,MATCH('Item Lookup'!$C$4,'Item List'!$A$5:$A$500,0)),"")
A8: Last Price Paid: | C8: =IFERROR(INDEX('All Data'!$H$5:$H$2001,MATCH(1,('All Data'!$J$5:$J$2001='Item Lookup'!$C$4)*('All Data'!$A$5:$A$2001=C9),0)),"")
A9: Last Purchase Date: | C9: =IFERROR(MAX(IF('All Data'!$J$5:$J$2001='Item Lookup'!$C$4,'All Data'!$A$5:$A$2001)),"No purchases yet")
A10: Last Location: | C10: =IFERROR(INDEX('All Data'!$B$5:$B$2001,MATCH(1,('All Data'!$J$5:$J$2001='Item Lookup'!$C$4)*('All Data'!$A$5:$A$2001=C9),0)),"")
A11: Previous Price (before that): | C11: =IFERROR(LARGE(IF(('All Data'!$J$5:$J$2001='Item Lookup'!$C$4)*('All Data'!$A$5:$A$2001<>C9),'All Data'!$A$5:$A$2001),1),"") | D11: (date) | E11: =IFERROR(INDEX('All Data'!$H$5:$H$2001,MATCH(1,('All Data'!$J$5:$J$2001='Item Lookup'!$C$4)*('All Data'!$A$5:$A$2001=C11),0)),"") | F11: (price)
A12: Change vs Previous: | C12: =IF(OR(C8="",E11=""),"",C8-E11) | D12: =IF(OR(C8="",E11="",E11=0),"",TEXT((C8-E11)/E11,"+0.0%;-0.0%"))
A13: Lowest Price Ever: | C13: =IFERROR(MIN(IF('All Data'!$J$5:$J$2001='Item Lookup'!$C$4,'All Data'!$H$5:$H$2001)),"")
A14: ...at Location: | C14: =IFERROR(INDEX('All Data'!$B$5:$B$2001,MATCH(1,('All Data'!$J$5:$J$2001='Item Lookup'!$C$4)*('All Data'!$H$5:$H$2001=C13),0)),"")
A15: Highest Price Ever: | C15: =IFERROR(MAX(IF('All Data'!$J$5:$J$2001='Item Lookup'!$C$4,'All Data'!$H$5:$H$2001)),"")
A16: ...at Location: | C16: =IFERROR(INDEX('All Data'!$B$5:$B$2001,MATCH(1,('All Data'!$J$5:$J$2001='Item Lookup'!$C$4)*('All Data'!$H$5:$H$2001=C15),0)),"")
A17: Times Purchased: | C17: =COUNTIFS('All Data'!$J$5:$J$2001,'Item Lookup'!$C$4)
A19: Full Purchase History for this Item
A20: Date | B20: Location | C20: Supplier | D20: Qty | E20: Unit Price ($) | F20: Amount ($) | G20: Change vs Prev ($) | H20: Flag
A21: =IFERROR(LARGE(IF('All Data'!$J$5:$J$2001='Item Lookup'!$C$4,'All Data'!$A$5:$A$2001),1),"") | B21: =IF($A21="","",IFERROR(INDEX('All Data'!$B$5:$B$2001,MATCH(1,('All Data'!$J$5:$J$2001='Item Lookup'!$C$4)*('All Data'!$A$5:$A$2001=$A21),0)),"")) | C21: =IF($A21="","",IFERROR(INDEX('All Data'!$C$5:$C$2001,MATCH(1,('All Data'!$J$5:$J$2001='Item Lookup'!$C$4)*('All Data'!$A$5:$A$2001=$A21),0)),"")) | D21: =IF($A21="","",IFERROR(INDEX('All Data'!$G$5:$G$2001,MATCH(1,('All Data'!$J$5:$J$2001='Item Lookup'!$C$4)*('All Data'!$A$5:$A$2001=$A21),0)),"")) | E21: =IF($A21="","",IFERROR(INDEX('All Data'!$H$5:$H$2001,MATCH(1,('All Data'!$J$5:$J$2001='Item Lookup'!$C$4)*('All Data'!$A$5:$A$2001=$A21),0)),"")) | F21: =IF($A21="","",IFERROR(INDEX('All Data'!$I$5:$I$2001,MATCH(1,('All Data'!$J$5:$J$2001='Item Lookup'!$C$4)*('All Data'!$A$5:$A$2001=$A21),0)),"")) | G21: =IF($A21="","",IFERROR(INDEX('All Data'!$L$5:$L$2001,MATCH(1,('All Data'!$J$5:$J$2001='Item Lookup'!$C$4)*('All Data'!$A$5:$A$2001=$A21),0)),"")) | H21: =IF($A21="","",IFERROR(INDEX('All Data'!$N$5:$N$2001,MATCH(1,('All Data'!$J$5:$J$2001='Item Lookup'!$C$4)*('All Data'!$A$5:$A$2001=$A21),0)),""))
A22: =IFERROR(LARGE(IF('All Data'!$J$5:$J$2001='Item Lookup'!$C$4,'All Data'!$A$5:$A$2001),2),"") | B22: =IF($A22="","",IFERROR(INDEX('All Data'!$B$5:$B$2001,MATCH(1,('All Data'!$J$5:$J$2001='Item Lookup'!$C$4)*('All Data'!$A$5:$A$2001=$A22),0)),"")) | C22: =IF($A22="","",IFERROR(INDEX('All Data'!$C$5:$C$2001,MATCH(1,('All Data'!$J$5:$J$2001='Item Lookup'!$C$4)*('All Data'!$A$5:$A$2001=$A22),0)),"")) | D22: =IF($A22="","",IFERROR(INDEX('All Data'!$G$5:$G$2001,MATCH(1,('All Data'!$J$5:$J$2001='Item Lookup'!$C$4)*('All Data'!$A$5:$A$2001=$A22),0)),"")) | E22: =IF($A22="","",IFERROR(INDEX('All Data'!$H$5:$H$2001,MATCH(1,('All Data'!$J$5:$J$2001='Item Lookup'!$C$4)*('All Data'!$A$5:$A$2001=$A22),0)),"")) | F22: =IF($A22="","",IFERROR(INDEX('All Data'!$I$5:$I$2001,MATCH(1,('All Data'!$J$5:$J$2001='Item Lookup'!$C$4)*('All Data'!$A$5:$A$2001=$A22),0)),"")) | G22: =IF($A22="","",IFERROR(INDEX('All Data'!$L$5:$L$2001,MATCH(1,('All Data'!$J$5:$J$2001='Item Lookup'!$C$4)*('All Data'!$A$5:$A$2001=$A22),0)),"")) | H22: =IF($A22="","",IFERROR(INDEX('All Data'!$N$5:$N$2001,MATCH(1,('All Data'!$J$5:$J$2001='Item Lookup'!$C$4)*('All Data'!$A$5:$A$2001=$A22),0)),""))
A23: =IFERROR(LARGE(IF('All Data'!$J$5:$J$2001='Item Lookup'!$C$4,'All Data'!$A$5:$A$2001),3),"") | B23: =IF($A23="","",IFERROR(INDEX('All Data'!$B$5:$B$2001,MATCH(1,('All Data'!$J$5:$J$2001='Item Lookup'!$C$4)*('All Data'!$A$5:$A$2001=$A23),0)),"")) | C23: =IF($A23="","",IFERROR(INDEX('All Data'!$C$5:$C$2001,MATCH(1,('All Data'!$J$5:$J$2001='Item Lookup'!$C$4)*('All Data'!$A$5:$A$2001=$A23),0)),"")) | D23: =IF($A23="","",IFERROR(INDEX('All Data'!$G$5:$G$2001,MATCH(1,('All Data'!$J$5:$J$2001='Item Lookup'!$C$4)*('All Data'!$A$5:$A$2001=$A23),0)),"")) | E23: =IF($A23="","",IFERROR(INDEX('All Data'!$H$5:$H$2001,MATCH(1,('All Data'!$J$5:$J$2001='Item Lookup'!$C$4)*('All Data'!$A$5:$A$2001=$A23),0)),"")) | F23: =IF($A23="","",IFERROR(INDEX('All Data'!$I$5:$I$2001,MATCH(1,('All Data'!$J$5:$J$2001='Item Lookup'!$C$4)*('All Data'!$A$5:$A$2001=$A23),0)),"")) | G23: =IF($A23="","",IFERROR(INDEX('All Data'!$L$5:$L$2001,MATCH(1,('All Data'!$J$5:$J$2001='Item Lookup'!$C$4)*('All Data'!$A$5:$A$2001=$A23),0)),"")) | H23: =IF($A23="","",IFERROR(INDEX('All Data'!$N$5:$N$2001,MATCH(1,('All Data'!$J$5:$J$2001='Item Lookup'!$C$4)*('All Data'!$A$5:$A$2001=$A23),0)),""))
A24: =IFERROR(LARGE(IF('All Data'!$J$5:$J$2001='Item Lookup'!$C$4,'All Data'!$A$5:$A$2001),4),"") | B24: =IF($A24="","",IFERROR(INDEX('All Data'!$B$5:$B$2001,MATCH(1,('All Data'!$J$5:$J$2001='Item Lookup'!$C$4)*('All Data'!$A$5:$A$2001=$A24),0)),"")) | C24: =IF($A24="","",IFERROR(INDEX('All Data'!$C$5:$C$2001,MATCH(1,('All Data'!$J$5:$J$2001='Item Lookup'!$C$4)*('All Data'!$A$5:$A$2001=$A24),0)),"")) | D24: =IF($A24="","",IFERROR(INDEX('All Data'!$G$5:$G$2001,MATCH(1,('All Data'!$J$5:$J$2001='Item Lookup'!$C$4)*('All Data'!$A$5:$A$2001=$A24),0)),"")) | E24: =IF($A24="","",IFERROR(INDEX('All Data'!$H$5:$H$2001,MATCH(1,('All Data'!$J$5:$J$2001='Item Lookup'!$C$4)*('All Data'!$A$5:$A$2001=$A24),0)),"")) | F24: =IF($A24="","",IFERROR(INDEX('All Data'!$I$5:$I$2001,MATCH(1,('All Data'!$J$5:$J$2001='Item Lookup'!$C$4)*('All Data'!$A$5:$A$2001=$A24),0)),"")) | G24: =IF($A24="","",IFERROR(INDEX('All Data'!$L$5:$L$2001,MATCH(1,('All Data'!$J$5:$J$2001='Item Lookup'!$C$4)*('All Data'!$A$5:$A$2001=$A24),0)),"")) | H24: =IF($A24="","",IFERROR(INDEX('All Data'!$N$5:$N$2001,MATCH(1,('All Data'!$J$5:$J$2001='Item Lookup'!$C$4)*('All Data'!$A$5:$A$2001=$A24),0)),""))
A25: =IFERROR(LARGE(IF('All Data'!$J$5:$J$2001='Item Lookup'!$C$4,'All Data'!$A$5:$A$2001),5),"") | B25: =IF($A25="","",IFERROR(INDEX('All Data'!$B$5:$B$2001,MATCH(1,('All Data'!$J$5:$J$2001='Item Lookup'!$C$4)*('All Data'!$A$5:$A$2001=$A25),0)),"")) | C25: =IF($A25="","",IFERROR(INDEX('All Data'!$C$5:$C$2001,MATCH(1,('All Data'!$J$5:$J$2001='Item Lookup'!$C$4)*('All Data'!$A$5:$A$2001=$A25),0)),"")) | D25: =IF($A25="","",IFERROR(INDEX('All Data'!$G$5:$G$2001,MATCH(1,('All Data'!$J$5:$J$2001='Item Lookup'!$C$4)*('All Data'!$A$5:$A$2001=$A25),0)),"")) | E25: =IF($A25="","",IFERROR(INDEX('All Data'!$H$5:$H$2001,MATCH(1,('All Data'!$J$5:$J$2001='Item Lookup'!$C$4)*('All Data'!$A$5:$A$2001=$A25),0)),"")) | F25: =IF($A25="","",IFERROR(INDEX('All Data'!$I$5:$I$2001,MATCH(1,('All Data'!$J$5:$J$2001='Item Lookup'!$C$4)*('All Data'!$A$5:$A$2001=$A25),0)),"")) | G25: =IF($A25="","",IFERROR(INDEX('All Data'!$L$5:$L$2001,MATCH(1,('All Data'!$J$5:$J$2001='Item Lookup'!$C$4)*('All Data'!$A$5:$A$2001=$A25),0)),"")) | H25: =IF($A25="","",IFERROR(INDEX('All Data'!$N$5:$N$2001,MATCH(1,('All Data'!$J$5:$J$2001='Item Lookup'!$C$4)*('All Data'!$A$5:$A$2001=$A25),0)),""))
A26: =IFERROR(LARGE(IF('All Data'!$J$5:$J$2001='Item Lookup'!$C$4,'All Data'!$A$5:$A$2001),6),"") | B26: =IF($A26="","",IFERROR(INDEX('All Data'!$B$5:$B$2001,MATCH(1,('All Data'!$J$5:$J$2001='Item Lookup'!$C$4)*('All Data'!$A$5:$A$2001=$A26),0)),"")) | C26: =IF($A26="","",IFERROR(INDEX('All Data'!$C$5:$C$2001,MATCH(1,('All Data'!$J$5:$J$2001='Item Lookup'!$C$4)*('All Data'!$A$5:$A$2001=$A26),0)),"")) | D26: =IF($A26="","",IFERROR(INDEX('All Data'!$G$5:$G$2001,MATCH(1,('All Data'!$J$5:$J$2001='Item Lookup'!$C$4)*('All Data'!$A$5:$A$2001=$A26),0)),"")) | E26: =IF($A26="","",IFERROR(INDEX('All Data'!$H$5:$H$2001,MATCH(1,('All Data'!$J$5:$J$2001='Item Lookup'!$C$4)*('All Data'!$A$5:$A$2001=$A26),0)),"")) | F26: =IF($A26="","",IFERROR(INDEX('All Data'!$I$5:$I$2001,MATCH(1,('All Data'!$J$5:$J$2001='Item Lookup'!$C$4)*('All Data'!$A$5:$A$2001=$A26),0)),"")) | G26: =IF($A26="","",IFERROR(INDEX('All Data'!$L$5:$L$2001,MATCH(1,('All Data'!$J$5:$J$2001='Item Lookup'!$C$4)*('All Data'!$A$5:$A$2001=$A26),0)),"")) | H26: =IF($A26="","",IFERROR(INDEX('All Data'!$N$5:$N$2001,MATCH(1,('All Data'!$J$5:$J$2001='Item Lookup'!$C$4)*('All Data'!$A$5:$A$2001=$A26),0)),""))
A27: =IFERROR(LARGE(IF('All Data'!$J$5:$J$2001='Item Lookup'!$C$4,'All Data'!$A$5:$A$2001),7),"") | B27: =IF($A27="","",IFERROR(INDEX('All Data'!$B$5:$B$2001,MATCH(1,('All Data'!$J$5:$J$2001='Item Lookup'!$C$4)*('All Data'!$A$5:$A$2001=$A27),0)),"")) | C27: =IF($A27="","",IFERROR(INDEX('All Data'!$C$5:$C$2001,MATCH(1,('All Data'!$J$5:$J$2001='Item Lookup'!$C$4)*('All Data'!$A$5:$A$2001=$A27),0)),"")) | D27: =IF($A27="","",IFERROR(INDEX('All Data'!$G$5:$G$2001,MATCH(1,('All Data'!$J$5:$J$2001='Item Lookup'!$C$4)*('All Data'!$A$5:$A$2001=$A27),0)),"")) | E27: =IF($A27="","",IFERROR(INDEX('All Data'!$H$5:$H$2001,MATCH(1,('All Data'!$J$5:$J$2001='Item Lookup'!$C$4)*('All Data'!$A$5:$A$2001=$A27),0)),"")) | F27: =IF($A27="","",IFERROR(INDEX('All Data'!$I$5:$I$2001,MATCH(1,('All Data'!$J$5:$J$2001='Item Lookup'!$C$4)*('All Data'!$A$5:$A$2001=$A27),0)),"")) | G27: =IF($A27="","",IFERROR(INDEX('All Data'!$L$5:$L$2001,MATCH(1,('All Data'!$J$5:$J$2001='Item Lookup'!$C$4)*('All Data'!$A$5:$A$2001=$A27),0)),"")) | H27: =IF($A27="","",IFERROR(INDEX('All Data'!$N$5:$N$2001,MATCH(1,('All Data'!$J$5:$J$2001='Item Lookup'!$C$4)*('All Data'!$A$5:$A$2001=$A27),0)),""))
A28: =IFERROR(LARGE(IF('All Data'!$J$5:$J$2001='Item Lookup'!$C$4,'All Data'!$A$5:$A$2001),8),"") | B28: =IF($A28="","",IFERROR(INDEX('All Data'!$B$5:$B$2001,MATCH(1,('All Data'!$J$5:$J$2001='Item Lookup'!$C$4)*('All Data'!$A$5:$A$2001=$A28),0)),"")) | C28: =IF($A28="","",IFERROR(INDEX('All Data'!$C$5:$C$2001,MATCH(1,('All Data'!$J$5:$J$2001='Item Lookup'!$C$4)*('All Data'!$A$5:$A$2001=$A28),0)),"")) | D28: =IF($A28="","",IFERROR(INDEX('All Data'!$G$5:$G$2001,MATCH(1,('All Data'!$J$5:$J$2001='Item Lookup'!$C$4)*('All Data'!$A$5:$A$2001=$A28),0)),"")) | E28: =IF($A28="","",IFERROR(INDEX('All Data'!$H$5:$H$2001,MATCH(1,('All Data'!$J$5:$J$2001='Item Lookup'!$C$4)*('All Data'!$A$5:$A$2001=$A28),0)),"")) | F28: =IF($A28="","",IFERROR(INDEX('All Data'!$I$5:$I$2001,MATCH(1,('All Data'!$J$5:$J$2001='Item Lookup'!$C$4)*('All Data'!$A$5:$A$2001=$A28),0)),"")) | G28: =IF($A28="","",IFERROR(INDEX('All Data'!$L$5:$L$2001,MATCH(1,('All Data'!$J$5:$J$2001='Item Lookup'!$C$4)*('All Data'!$A$5:$A$2001=$A28),0)),"")) | H28: =IF($A28="","",IFERROR(INDEX('All Data'!$N$5:$N$2001,MATCH(1,('All Data'!$J$5:$J$2001='Item Lookup'!$C$4)*('All Data'!$A$5:$A$2001=$A28),0)),""))
A29: =IFERROR(LARGE(IF('All Data'!$J$5:$J$2001='Item Lookup'!$C$4,'All Data'!$A$5:$A$2001),9),"") | B29: =IF($A29="","",IFERROR(INDEX('All Data'!$B$5:$B$2001,MATCH(1,('All Data'!$J$5:$J$2001='Item Lookup'!$C$4)*('All Data'!$A$5:$A$2001=$A29),0)),"")) | C29: =IF($A29="","",IFERROR(INDEX('All Data'!$C$5:$C$2001,MATCH(1,('All Data'!$J$5:$J$2001='Item Lookup'!$C$4)*('All Data'!$A$5:$A$2001=$A29),0)),"")) | D29: =IF($A29="","",IFERROR(INDEX('All Data'!$G$5:$G$2001,MATCH(1,('All Data'!$J$5:$J$2001='Item Lookup'!$C$4)*('All Data'!$A$5:$A$2001=$A29),0)),"")) | E29: =IF($A29="","",IFERROR(INDEX('All Data'!$H$5:$H$2001,MATCH(1,('All Data'!$J$5:$J$2001='Item Lookup'!$C$4)*('All Data'!$A$5:$A$2001=$A29),0)),"")) | F29: =IF($A29="","",IFERROR(INDEX('All Data'!$I$5:$I$2001,MATCH(1,('All Data'!$J$5:$J$2001='Item Lookup'!$C$4)*('All Data'!$A$5:$A$2001=$A29),0)),"")) | G29: =IF($A29="","",IFERROR(INDEX('All Data'!$L$5:$L$2001,MATCH(1,('All Data'!$J$5:$J$2001='Item Lookup'!$C$4)*('All Data'!$A$5:$A$2001=$A29),0)),"")) | H29: =IF($A29="","",IFERROR(INDEX('All Data'!$N$5:$N$2001,MATCH(1,('All Data'!$J$5:$J$2001='Item Lookup'!$C$4)*('All Data'!$A$5:$A$2001=$A29),0)),""))
A30: =IFERROR(LARGE(IF('All Data'!$J$5:$J$2001='Item Lookup'!$C$4,'All Data'!$A$5:$A$2001),10),"") | B30: =IF($A30="","",IFERROR(INDEX('All Data'!$B$5:$B$2001,MATCH(1,('All Data'!$J$5:$J$2001='Item Lookup'!$C$4)*('All Data'!$A$5:$A$2001=$A30),0)),"")) | C30: =IF($A30="","",IFERROR(INDEX('All Data'!$C$5:$C$2001,MATCH(1,('All Data'!$J$5:$J$2001='Item Lookup'!$C$4)*('All Data'!$A$5:$A$2001=$A30),0)),"")) | D30: =IF($A30="","",IFERROR(INDEX('All Data'!$G$5:$G$2001,MATCH(1,('All Data'!$J$5:$J$2001='Item Lookup'!$C$4)*('All Data'!$A$5:$A$2001=$A30),0)),"")) | E30: =IF($A30="","",IFERROR(INDEX('All Data'!$H$5:$H$2001,MATCH(1,('All Data'!$J$5:$J$2001='Item Lookup'!$C$4)*('All Data'!$A$5:$A$2001=$A30),0)),"")) | F30: =IF($A30="","",IFERROR(INDEX('All Data'!$I$5:$I$2001,MATCH(1,('All Data'!$J$5:$J$2001='Item Lookup'!$C$4)*('All Data'!$A$5:$A$2001=$A30),0)),"")) | G30: =IF($A30="","",IFERROR(INDEX('All Data'!$L$5:$L$2001,MATCH(1,('All Data'!$J$5:$J$2001='Item Lookup'!$C$4)*('All Data'!$A$5:$A$2001=$A30),0)),"")) | H30: =IF($A30="","",IFERROR(INDEX('All Data'!$N$5:$N$2001,MATCH(1,('All Data'!$J$5:$J$2001='Item Lookup'!$C$4)*('All Data'!$A$5:$A$2001=$A30),0)),""))
A31: =IFERROR(LARGE(IF('All Data'!$J$5:$J$2001='Item Lookup'!$C$4,'All Data'!$A$5:$A$2001),11),"") | B31: =IF($A31="","",IFERROR(INDEX('All Data'!$B$5:$B$2001,MATCH(1,('All Data'!$J$5:$J$2001='Item Lookup'!$C$4)*('All Data'!$A$5:$A$2001=$A31),0)),"")) | C31: =IF($A31="","",IFERROR(INDEX('All Data'!$C$5:$C$2001,MATCH(1,('All Data'!$J$5:$J$2001='Item Lookup'!$C$4)*('All Data'!$A$5:$A$2001=$A31),0)),"")) | D31: =IF($A31="","",IFERROR(INDEX('All Data'!$G$5:$G$2001,MATCH(1,('All Data'!$J$5:$J$2001='Item Lookup'!$C$4)*('All Data'!$A$5:$A$2001=$A31),0)),"")) | E31: =IF($A31="","",IFERROR(INDEX('All Data'!$H$5:$H$2001,MATCH(1,('All Data'!$J$5:$J$2001='Item Lookup'!$C$4)*('All Data'!$A$5:$A$2001=$A31),0)),"")) | F31: =IF($A31="","",IFERROR(INDEX('All Data'!$I$5:$I$2001,MATCH(1,('All Data'!$J$5:$J$2001='Item Lookup'!$C$4)*('All Data'!$A$5:$A$2001=$A31),0)),"")) | G31: =IF($A31="","",IFERROR(INDEX('All Data'!$L$5:$L$2001,MATCH(1,('All Data'!$J$5:$J$2001='Item Lookup'!$C$4)*('All Data'!$A$5:$A$2001=$A31),0)),"")) | H31: =IF($A31="","",IFERROR(INDEX('All Data'!$N$5:$N$2001,MATCH(1,('All Data'!$J$5:$J$2001='Item Lookup'!$C$4)*('All Data'!$A$5:$A$2001=$A31),0)),""))
A32: =IFERROR(LARGE(IF('All Data'!$J$5:$J$2001='Item Lookup'!$C$4,'All Data'!$A$5:$A$2001),12),"") | B32: =IF($A32="","",IFERROR(INDEX('All Data'!$B$5:$B$2001,MATCH(1,('All Data'!$J$5:$J$2001='Item Lookup'!$C$4)*('All Data'!$A$5:$A$2001=$A32),0)),"")) | C32: =IF($A32="","",IFERROR(INDEX('All Data'!$C$5:$C$2001,MATCH(1,('All Data'!$J$5:$J$2001='Item Lookup'!$C$4)*('All Data'!$A$5:$A$2001=$A32),0)),"")) | D32: =IF($A32="","",IFERROR(INDEX('All Data'!$G$5:$G$2001,MATCH(1,('All Data'!$J$5:$J$2001='Item Lookup'!$C$4)*('All Data'!$A$5:$A$2001=$A32),0)),"")) | E32: =IF($A32="","",IFERROR(INDEX('All Data'!$H$5:$H$2001,MATCH(1,('All Data'!$J$5:$J$2001='Item Lookup'!$C$4)*('All Data'!$A$5:$A$2001=$A32),0)),"")) | F32: =IF($A32="","",IFERROR(INDEX('All Data'!$I$5:$I$2001,MATCH(1,('All Data'!$J$5:$J$2001='Item Lookup'!$C$4)*('All Data'!$A$5:$A$2001=$A32),0)),"")) | G32: =IF($A32="","",IFERROR(INDEX('All Data'!$L$5:$L$2001,MATCH(1,('All Data'!$J$5:$J$2001='Item Lookup'!$C$4)*('All Data'!$A$5:$A$2001=$A32),0)),"")) | H32: =IF($A32="","",IFERROR(INDEX('All Data'!$N$5:$N$2001,MATCH(1,('All Data'!$J$5:$J$2001='Item Lookup'!$C$4)*('All Data'!$A$5:$A$2001=$A32),0)),""))
A33: =IFERROR(LARGE(IF('All Data'!$J$5:$J$2001='Item Lookup'!$C$4,'All Data'!$A$5:$A$2001),13),"") | B33: =IF($A33="","",IFERROR(INDEX('All Data'!$B$5:$B$2001,MATCH(1,('All Data'!$J$5:$J$2001='Item Lookup'!$C$4)*('All Data'!$A$5:$A$2001=$A33),0)),"")) | C33: =IF($A33="","",IFERROR(INDEX('All Data'!$C$5:$C$2001,MATCH(1,('All Data'!$J$5:$J$2001='Item Lookup'!$C$4)*('All Data'!$A$5:$A$2001=$A33),0)),"")) | D33: =IF($A33="","",IFERROR(INDEX('All Data'!$G$5:$G$2001,MATCH(1,('All Data'!$J$5:$J$2001='Item Lookup'!$C$4)*('All Data'!$A$5:$A$2001=$A33),0)),"")) | E33: =IF($A33="","",IFERROR(INDEX('All Data'!$H$5:$H$2001,MATCH(1,('All Data'!$J$5:$J$2001='Item Lookup'!$C$4)*('All Data'!$A$5:$A$2001=$A33),0)),"")) | F33: =IF($A33="","",IFERROR(INDEX('All Data'!$I$5:$I$2001,MATCH(1,('All Data'!$J$5:$J$2001='Item Lookup'!$C$4)*('All Data'!$A$5:$A$2001=$A33),0)),"")) | G33: =IF($A33="","",IFERROR(INDEX('All Data'!$L$5:$L$2001,MATCH(1,('All Data'!$J$5:$J$2001='Item Lookup'!$C$4)*('All Data'!$A$5:$A$2001=$A33),0)),"")) | H33: =IF($A33="","",IFERROR(INDEX('All Data'!$N$5:$N$2001,MATCH(1,('All Data'!$J$5:$J$2001='Item Lookup'!$C$4)*('All Data'!$A$5:$A$2001=$A33),0)),""))
A34: =IFERROR(LARGE(IF('All Data'!$J$5:$J$2001='Item Lookup'!$C$4,'All Data'!$A$5:$A$2001),14),"") | B34: =IF($A34="","",IFERROR(INDEX('All Data'!$B$5:$B$2001,MATCH(1,('All Data'!$J$5:$J$2001='Item Lookup'!$C$4)*('All Data'!$A$5:$A$2001=$A34),0)),"")) | C34: =IF($A34="","",IFERROR(INDEX('All Data'!$C$5:$C$2001,MATCH(1,('All Data'!$J$5:$J$2001='Item Lookup'!$C$4)*('All Data'!$A$5:$A$2001=$A34),0)),"")) | D34: =IF($A34="","",IFERROR(INDEX('All Data'!$G$5:$G$2001,MATCH(1,('All Data'!$J$5:$J$2001='Item Lookup'!$C$4)*('All Data'!$A$5:$A$2001=$A34),0)),"")) | E34: =IF($A34="","",IFERROR(INDEX('All Data'!$H$5:$H$2001,MATCH(1,('All Data'!$J$5:$J$2001='Item Lookup'!$C$4)*('All Data'!$A$5:$A$2001=$A34),0)),"")) | F34: =IF($A34="","",IFERROR(INDEX('All Data'!$I$5:$I$2001,MATCH(1,('All Data'!$J$5:$J$2001='Item Lookup'!$C$4)*('All Data'!$A$5:$A$2001=$A34),0)),"")) | G34: =IF($A34="","",IFERROR(INDEX('All Data'!$L$5:$L$2001,MATCH(1,('All Data'!$J$5:$J$2001='Item Lookup'!$C$4)*('All Data'!$A$5:$A$2001=$A34),0)),"")) | H34: =IF($A34="","",IFERROR(INDEX('All Data'!$N$5:$N$2001,MATCH(1,('All Data'!$J$5:$J$2001='Item Lookup'!$C$4)*('All Data'!$A$5:$A$2001=$A34),0)),""))
A35: =IFERROR(LARGE(IF('All Data'!$J$5:$J$2001='Item Lookup'!$C$4,'All Data'!$A$5:$A$2001),15),"") | B35: =IF($A35="","",IFERROR(INDEX('All Data'!$B$5:$B$2001,MATCH(1,('All Data'!$J$5:$J$2001='Item Lookup'!$C$4)*('All Data'!$A$5:$A$2001=$A35),0)),"")) | C35: =IF($A35="","",IFERROR(INDEX('All Data'!$C$5:$C$2001,MATCH(1,('All Data'!$J$5:$J$2001='Item Lookup'!$C$4)*('All Data'!$A$5:$A$2001=$A35),0)),"")) | D35: =IF($A35="","",IFERROR(INDEX('All Data'!$G$5:$G$2001,MATCH(1,('All Data'!$J$5:$J$2001='Item Lookup'!$C$4)*('All Data'!$A$5:$A$2001=$A35),0)),"")) | E35: =IF($A35="","",IFERROR(INDEX('All Data'!$H$5:$H$2001,MATCH(1,('All Data'!$J$5:$J$2001='Item Lookup'!$C$4)*('All Data'!$A$5:$A$2001=$A35),0)),"")) | F35: =IF($A35="","",IFERROR(INDEX('All Data'!$I$5:$I$2001,MATCH(1,('All Data'!$J$5:$J$2001='Item Lookup'!$C$4)*('All Data'!$A$5:$A$2001=$A35),0)),"")) | G35: =IF($A35="","",IFERROR(INDEX('All Data'!$L$5:$L$2001,MATCH(1,('All Data'!$J$5:$J$2001='Item Lookup'!$C$4)*('All Data'!$A$5:$A$2001=$A35),0)),"")) | H35: =IF($A35="","",IFERROR(INDEX('All Data'!$N$5:$N$2001,MATCH(1,('All Data'!$J$5:$J$2001='Item Lookup'!$C$4)*('All Data'!$A$5:$A$2001=$A35),0)),""))
A36: =IFERROR(LARGE(IF('All Data'!$J$5:$J$2001='Item Lookup'!$C$4,'All Data'!$A$5:$A$2001),16),"") | B36: =IF($A36="","",IFERROR(INDEX('All Data'!$B$5:$B$2001,MATCH(1,('All Data'!$J$5:$J$2001='Item Lookup'!$C$4)*('All Data'!$A$5:$A$2001=$A36),0)),"")) | C36: =IF($A36="","",IFERROR(INDEX('All Data'!$C$5:$C$2001,MATCH(1,('All Data'!$J$5:$J$2001='Item Lookup'!$C$4)*('All Data'!$A$5:$A$2001=$A36),0)),"")) | D36: =IF($A36="","",IFERROR(INDEX('All Data'!$G$5:$G$2001,MATCH(1,('All Data'!$J$5:$J$2001='Item Lookup'!$C$4)*('All Data'!$A$5:$A$2001=$A36),0)),"")) | E36: =IF($A36="","",IFERROR(INDEX('All Data'!$H$5:$H$2001,MATCH(1,('All Data'!$J$5:$J$2001='Item Lookup'!$C$4)*('All Data'!$A$5:$A$2001=$A36),0)),"")) | F36: =IF($A36="","",IFERROR(INDEX('All Data'!$I$5:$I$2001,MATCH(1,('All Data'!$J$5:$J$2001='Item Lookup'!$C$4)*('All Data'!$A$5:$A$2001=$A36),0)),"")) | G36: =IF($A36="","",IFERROR(INDEX('All Data'!$L$5:$L$2001,MATCH(1,('All Data'!$J$5:$J$2001='Item Lookup'!$C$4)*('All Data'!$A$5:$A$2001=$A36),0)),"")) | H36: =IF($A36="","",IFERROR(INDEX('All Data'!$N$5:$N$2001,MATCH(1,('All Data'!$J$5:$J$2001='Item Lookup'!$C$4)*('All Data'!$A$5:$A$2001=$A36),0)),""))
A37: =IFERROR(LARGE(IF('All Data'!$J$5:$J$2001='Item Lookup'!$C$4,'All Data'!$A$5:$A$2001),17),"") | B37: =IF($A37="","",IFERROR(INDEX('All Data'!$B$5:$B$2001,MATCH(1,('All Data'!$J$5:$J$2001='Item Lookup'!$C$4)*('All Data'!$A$5:$A$2001=$A37),0)),"")) | C37: =IF($A37="","",IFERROR(INDEX('All Data'!$C$5:$C$2001,MATCH(1,('All Data'!$J$5:$J$2001='Item Lookup'!$C$4)*('All Data'!$A$5:$A$2001=$A37),0)),"")) | D37: =IF($A37="","",IFERROR(INDEX('All Data'!$G$5:$G$2001,MATCH(1,('All Data'!$J$5:$J$2001='Item Lookup'!$C$4)*('All Data'!$A$5:$A$2001=$A37),0)),"")) | E37: =IF($A37="","",IFERROR(INDEX('All Data'!$H$5:$H$2001,MATCH(1,('All Data'!$J$5:$J$2001='Item Lookup'!$C$4)*('All Data'!$A$5:$A$2001=$A37),0)),"")) | F37: =IF($A37="","",IFERROR(INDEX('All Data'!$I$5:$I$2001,MATCH(1,('All Data'!$J$5:$J$2001='Item Lookup'!$C$4)*('All Data'!$A$5:$A$2001=$A37),0)),"")) | G37: =IF($A37="","",IFERROR(INDEX('All Data'!$L$5:$L$2001,MATCH(1,('All Data'!$J$5:$J$2001='Item Lookup'!$C$4)*('All Data'!$A$5:$A$2001=$A37),0)),"")) | H37: =IF($A37="","",IFERROR(INDEX('All Data'!$N$5:$N$2001,MATCH(1,('All Data'!$J$5:$J$2001='Item Lookup'!$C$4)*('All Data'!$A$5:$A$2001=$A37),0)),""))
A38: =IFERROR(LARGE(IF('All Data'!$J$5:$J$2001='Item Lookup'!$C$4,'All Data'!$A$5:$A$2001),18),"") | B38: =IF($A38="","",IFERROR(INDEX('All Data'!$B$5:$B$2001,MATCH(1,('All Data'!$J$5:$J$2001='Item Lookup'!$C$4)*('All Data'!$A$5:$A$2001=$A38),0)),"")) | C38: =IF($A38="","",IFERROR(INDEX('All Data'!$C$5:$C$2001,MATCH(1,('All Data'!$J$5:$J$2001='Item Lookup'!$C$4)*('All Data'!$A$5:$A$2001=$A38),0)),"")) | D38: =IF($A38="","",IFERROR(INDEX('All Data'!$G$5:$G$2001,MATCH(1,('All Data'!$J$5:$J$2001='Item Lookup'!$C$4)*('All Data'!$A$5:$A$2001=$A38),0)),"")) | E38: =IF($A38="","",IFERROR(INDEX('All Data'!$H$5:$H$2001,MATCH(1,('All Data'!$J$5:$J$2001='Item Lookup'!$C$4)*('All Data'!$A$5:$A$2001=$A38),0)),"")) | F38: =IF($A38="","",IFERROR(INDEX('All Data'!$I$5:$I$2001,MATCH(1,('All Data'!$J$5:$J$2001='Item Lookup'!$C$4)*('All Data'!$A$5:$A$2001=$A38),0)),"")) | G38: =IF($A38="","",IFERROR(INDEX('All Data'!$L$5:$L$2001,MATCH(1,('All Data'!$J$5:$J$2001='Item Lookup'!$C$4)*('All Data'!$A$5:$A$2001=$A38),0)),"")) | H38: =IF($A38="","",IFERROR(INDEX('All Data'!$N$5:$N$2001,MATCH(1,('All Data'!$J$5:$J$2001='Item Lookup'!$C$4)*('All Data'!$A$5:$A$2001=$A38),0)),""))
A39: =IFERROR(LARGE(IF('All Data'!$J$5:$J$2001='Item Lookup'!$C$4,'All Data'!$A$5:$A$2001),19),"") | B39: =IF($A39="","",IFERROR(INDEX('All Data'!$B$5:$B$2001,MATCH(1,('All Data'!$J$5:$J$2001='Item Lookup'!$C$4)*('All Data'!$A$5:$A$2001=$A39),0)),"")) | C39: =IF($A39="","",IFERROR(INDEX('All Data'!$C$5:$C$2001,MATCH(1,('All Data'!$J$5:$J$2001='Item Lookup'!$C$4)*('All Data'!$A$5:$A$2001=$A39),0)),"")) | D39: =IF($A39="","",IFERROR(INDEX('All Data'!$G$5:$G$2001,MATCH(1,('All Data'!$J$5:$J$2001='Item Lookup'!$C$4)*('All Data'!$A$5:$A$2001=$A39),0)),"")) | E39: =IF($A39="","",IFERROR(INDEX('All Data'!$H$5:$H$2001,MATCH(1,('All Data'!$J$5:$J$2001='Item Lookup'!$C$4)*('All Data'!$A$5:$A$2001=$A39),0)),"")) | F39: =IF($A39="","",IFERROR(INDEX('All Data'!$I$5:$I$2001,MATCH(1,('All Data'!$J$5:$J$2001='Item Lookup'!$C$4)*('All Data'!$A$5:$A$2001=$A39),0)),"")) | G39: =IF($A39="","",IFERROR(INDEX('All Data'!$L$5:$L$2001,MATCH(1,('All Data'!$J$5:$J$2001='Item Lookup'!$C$4)*('All Data'!$A$5:$A$2001=$A39),0)),"")) | H39: =IF($A39="","",IFERROR(INDEX('All Data'!$N$5:$N$2001,MATCH(1,('All Data'!$J$5:$J$2001='Item Lookup'!$C$4)*('All Data'!$A$5:$A$2001=$A39),0)),""))
A40: =IFERROR(LARGE(IF('All Data'!$J$5:$J$2001='Item Lookup'!$C$4,'All Data'!$A$5:$A$2001),20),"") | B40: =IF($A40="","",IFERROR(INDEX('All Data'!$B$5:$B$2001,MATCH(1,('All Data'!$J$5:$J$2001='Item Lookup'!$C$4)*('All Data'!$A$5:$A$2001=$A40),0)),"")) | C40: =IF($A40="","",IFERROR(INDEX('All Data'!$C$5:$C$2001,MATCH(1,('All Data'!$J$5:$J$2001='Item Lookup'!$C$4)*('All Data'!$A$5:$A$2001=$A40),0)),"")) | D40: =IF($A40="","",IFERROR(INDEX('All Data'!$G$5:$G$2001,MATCH(1,('All Data'!$J$5:$J$2001='Item Lookup'!$C$4)*('All Data'!$A$5:$A$2001=$A40),0)),"")) | E40: =IF($A40="","",IFERROR(INDEX('All Data'!$H$5:$H$2001,MATCH(1,('All Data'!$J$5:$J$2001='Item Lookup'!$C$4)*('All Data'!$A$5:$A$2001=$A40),0)),"")) | F40: =IF($A40="","",IFERROR(INDEX('All Data'!$I$5:$I$2001,MATCH(1,('All Data'!$J$5:$J$2001='Item Lookup'!$C$4)*('All Data'!$A$5:$A$2001=$A40),0)),"")) | G40: =IF($A40="","",IFERROR(INDEX('All Data'!$L$5:$L$2001,MATCH(1,('All Data'!$J$5:$J$2001='Item Lookup'!$C$4)*('All Data'!$A$5:$A$2001=$A40),0)),"")) | H40: =IF($A40="","",IFERROR(INDEX('All Data'!$N$5:$N$2001,MATCH(1,('All Data'!$J$5:$J$2001='Item Lookup'!$C$4)*('All Data'!$A$5:$A$2001=$A40),0)),""))
A41: =IFERROR(LARGE(IF('All Data'!$J$5:$J$2001='Item Lookup'!$C$4,'All Data'!$A$5:$A$2001),21),"") | B41: =IF($A41="","",IFERROR(INDEX('All Data'!$B$5:$B$2001,MATCH(1,('All Data'!$J$5:$J$2001='Item Lookup'!$C$4)*('All Data'!$A$5:$A$2001=$A41),0)),"")) | C41: =IF($A41="","",IFERROR(INDEX('All Data'!$C$5:$C$2001,MATCH(1,('All Data'!$J$5:$J$2001='Item Lookup'!$C$4)*('All Data'!$A$5:$A$2001=$A41),0)),"")) | D41: =IF($A41="","",IFERROR(INDEX('All Data'!$G$5:$G$2001,MATCH(1,('All Data'!$J$5:$J$2001='Item Lookup'!$C$4)*('All Data'!$A$5:$A$2001=$A41),0)),"")) | E41: =IF($A41="","",IFERROR(INDEX('All Data'!$H$5:$H$2001,MATCH(1,('All Data'!$J$5:$J$2001='Item Lookup'!$C$4)*('All Data'!$A$5:$A$2001=$A41),0)),"")) | F41: =IF($A41="","",IFERROR(INDEX('All Data'!$I$5:$I$2001,MATCH(1,('All Data'!$J$5:$J$2001='Item Lookup'!$C$4)*('All Data'!$A$5:$A$2001=$A41),0)),"")) | G41: =IF($A41="","",IFERROR(INDEX('All Data'!$L$5:$L$2001,MATCH(1,('All Data'!$J$5:$J$2001='Item Lookup'!$C$4)*('All Data'!$A$5:$A$2001=$A41),0)),"")) | H41: =IF($A41="","",IFERROR(INDEX('All Data'!$N$5:$N$2001,MATCH(1,('All Data'!$J$5:$J$2001='Item Lookup'!$C$4)*('All Data'!$A$5:$A$2001=$A41),0)),""))
A42: =IFERROR(LARGE(IF('All Data'!$J$5:$J$2001='Item Lookup'!$C$4,'All Data'!$A$5:$A$2001),22),"") | B42: =IF($A42="","",IFERROR(INDEX('All Data'!$B$5:$B$2001,MATCH(1,('All Data'!$J$5:$J$2001='Item Lookup'!$C$4)*('All Data'!$A$5:$A$2001=$A42),0)),"")) | C42: =IF($A42="","",IFERROR(INDEX('All Data'!$C$5:$C$2001,MATCH(1,('All Data'!$J$5:$J$2001='Item Lookup'!$C$4)*('All Data'!$A$5:$A$2001=$A42),0)),"")) | D42: =IF($A42="","",IFERROR(INDEX('All Data'!$G$5:$G$2001,MATCH(1,('All Data'!$J$5:$J$2001='Item Lookup'!$C$4)*('All Data'!$A$5:$A$2001=$A42),0)),"")) | E42: =IF($A42="","",IFERROR(INDEX('All Data'!$H$5:$H$2001,MATCH(1,('All Data'!$J$5:$J$2001='Item Lookup'!$C$4)*('All Data'!$A$5:$A$2001=$A42),0)),"")) | F42: =IF($A42="","",IFERROR(INDEX('All Data'!$I$5:$I$2001,MATCH(1,('All Data'!$J$5:$J$2001='Item Lookup'!$C$4)*('All Data'!$A$5:$A$2001=$A42),0)),"")) | G42: =IF($A42="","",IFERROR(INDEX('All Data'!$L$5:$L$2001,MATCH(1,('All Data'!$J$5:$J$2001='Item Lookup'!$C$4)*('All Data'!$A$5:$A$2001=$A42),0)),"")) | H42: =IF($A42="","",IFERROR(INDEX('All Data'!$N$5:$N$2001,MATCH(1,('All Data'!$J$5:$J$2001='Item Lookup'!$C$4)*('All Data'!$A$5:$A$2001=$A42),0)),""))
A43: =IFERROR(LARGE(IF('All Data'!$J$5:$J$2001='Item Lookup'!$C$4,'All Data'!$A$5:$A$2001),23),"") | B43: =IF($A43="","",IFERROR(INDEX('All Data'!$B$5:$B$2001,MATCH(1,('All Data'!$J$5:$J$2001='Item Lookup'!$C$4)*('All Data'!$A$5:$A$2001=$A43),0)),"")) | C43: =IF($A43="","",IFERROR(INDEX('All Data'!$C$5:$C$2001,MATCH(1,('All Data'!$J$5:$J$2001='Item Lookup'!$C$4)*('All Data'!$A$5:$A$2001=$A43),0)),"")) | D43: =IF($A43="","",IFERROR(INDEX('All Data'!$G$5:$G$2001,MATCH(1,('All Data'!$J$5:$J$2001='Item Lookup'!$C$4)*('All Data'!$A$5:$A$2001=$A43),0)),"")) | E43: =IF($A43="","",IFERROR(INDEX('All Data'!$H$5:$H$2001,MATCH(1,('All Data'!$J$5:$J$2001='Item Lookup'!$C$4)*('All Data'!$A$5:$A$2001=$A43),0)),"")) | F43: =IF($A43="","",IFERROR(INDEX('All Data'!$I$5:$I$2001,MATCH(1,('All Data'!$J$5:$J$2001='Item Lookup'!$C$4)*('All Data'!$A$5:$A$2001=$A43),0)),"")) | G43: =IF($A43="","",IFERROR(INDEX('All Data'!$L$5:$L$2001,MATCH(1,('All Data'!$J$5:$J$2001='Item Lookup'!$C$4)*('All Data'!$A$5:$A$2001=$A43),0)),"")) | H43: =IF($A43="","",IFERROR(INDEX('All Data'!$N$5:$N$2001,MATCH(1,('All Data'!$J$5:$J$2001='Item Lookup'!$C$4)*('All Data'!$A$5:$A$2001=$A43),0)),""))
...

Sheet Comparison
A1: Comparison - latest price per item, by Location
A2: One row per item (from Item List). One column per Location seen in your data. Shows the LATEST price you paid at that location. Min/Max/Diff highlight the cheapest option.
A4: Item Code | B4: Item Name | C4: Unit | D4: =IFERROR(INDEX(Lists!$A$2:$A$200,1),"") | E4: =IFERROR(INDEX(Lists!$A$2:$A$200,2),"") | F4: =IFERROR(INDEX(Lists!$A$2:$A$200,3),"") | G4: =IFERROR(INDEX(Lists!$A$2:$A$200,4),"") | H4: =IFERROR(INDEX(Lists!$A$2:$A$200,5),"") | I4: =IFERROR(INDEX(Lists!$A$2:$A$200,6),"") | J4: Min Price | K4: Max Price | L4: Diff ($) | M4: Cheapest At
A5: ='Item List'!A5 | B5: ='Item List'!B5 | C5: ='Item List'!C5 | D5: =IF(OR($A5="",D$4=""),"",IFERROR(INDEX('All Data'!$H$5:$H$2001,MATCH(1,('All Data'!$J$5:$J$2001=$A5)*('All Data'!$B$5:$B$2001=D$4)*('All Data'!$A$5:$A$2001=MAX(IF(('All Data'!$J$5:$J$2001=$A5)*('All Data'!$B$5:$B$2001=D$4),'All Data'!$A$5:$A$2001))),0)),"")) | E5: =IF(OR($A5="",E$4=""),"",IFERROR(INDEX('All Data'!$H$5:$H$2001,MATCH(1,('All Data'!$J$5:$J$2001=$A5)*('All Data'!$B$5:$B$2001=E$4)*('All Data'!$A$5:$A$2001=MAX(IF(('All Data'!$J$5:$J$2001=$A5)*('All Data'!$B$5:$B$2001=E$4),'All Data'!$A$5:$A$2001))),0)),"")) | F5: =IF(OR($A5="",F$4=""),"",IFERROR(INDEX('All Data'!$H$5:$H$2001,MATCH(1,('All Data'!$J$5:$J$2001=$A5)*('All Data'!$B$5:$B$2001=F$4)*('All Data'!$A$5:$A$2001=MAX(IF(('All Data'!$J$5:$J$2001=$A5)*('All Data'!$B$5:$B$2001=F$4),'All Data'!$A$5:$A$2001))),0)),"")) | G5: =IF(OR($A5="",G$4=""),"",IFERROR(INDEX('All Data'!$H$5:$H$2001,MATCH(1,('All Data'!$J$5:$J$2001=$A5)*('All Data'!$B$5:$B$2001=G$4)*('All Data'!$A$5:$A$2001=MAX(IF(('All Data'!$J$5:$J$2001=$A5)*('All Data'!$B$5:$B$2001=G$4),'All Data'!$A$5:$A$2001))),0)),"")) | H5: =IF(OR($A5="",H$4=""),"",IFERROR(INDEX('All Data'!$H$5:$H$2001,MATCH(1,('All Data'!$J$5:$J$2001=$A5)*('All Data'!$B$5:$B$2001=H$4)*('All Data'!$A$5:$A$2001=MAX(IF(('All Data'!$J$5:$J$2001=$A5)*('All Data'!$B$5:$B$2001=H$4),'All Data'!$A$5:$A$2001))),0)),"")) | I5: =IF(OR($A5="",I$4=""),"",IFERROR(INDEX('All Data'!$H$5:$H$2001,MATCH(1,('All Data'!$J$5:$J$2001=$A5)*('All Data'!$B$5:$B$2001=I$4)*('All Data'!$A$5:$A$2001=MAX(IF(('All Data'!$J$5:$J$2001=$A5)*('All Data'!$B$5:$B$2001=I$4),'All Data'!$A$5:$A$2001))),0)),"")) | J5: =IFERROR(MIN(D5,E5,F5,G5,H5,I5),"") | K5: =IFERROR(MAX(D5,E5,F5,G5,H5,I5),"") | L5: =IF(OR(J5="",K5=""),"",K5-J5) | M5: =IFERROR(INDEX($D$4:$I$4,MATCH(J5,$D5:$I5,0)),"")
A6: ='Item List'!A6 | B6: ='Item List'!B6 | C6: ='Item List'!C6 | D6: =IF(OR($A6="",D$4=""),"",IFERROR(INDEX('All Data'!$H$5:$H$2001,MATCH(1,('All Data'!$J$5:$J$2001=$A6)*('All Data'!$B$5:$B$2001=D$4)*('All Data'!$A$5:$A$2001=MAX(IF(('All Data'!$J$5:$J$2001=$A6)*('All Data'!$B$5:$B$2001=D$4),'All Data'!$A$5:$A$2001))),0)),"")) | E6: =IF(OR($A6="",E$4=""),"",IFERROR(INDEX('All Data'!$H$5:$H$2001,MATCH(1,('All Data'!$J$5:$J$2001=$A6)*('All Data'!$B$5:$B$2001=E$4)*('All Data'!$A$5:$A$2001=MAX(IF(('All Data'!$J$5:$J$2001=$A6)*('All Data'!$B$5:$B$2001=E$4),'All Data'!$A$5:$A$2001))),0)),"")) | F6: =IF(OR($A6="",F$4=""),"",IFERROR(INDEX('All Data'!$H$5:$H$2001,MATCH(1,('All Data'!$J$5:$J$2001=$A6)*('All Data'!$B$5:$B$2001=F$4)*('All Data'!$A$5:$A$2001=MAX(IF(('All Data'!$J$5:$J$2001=$A6)*('All Data'!$B$5:$B$2001=F$4),'All Data'!$A$5:$A$2001))),0)),"")) | G6: =IF(OR($A6="",G$4=""),"",IFERROR(INDEX('All Data'!$H$5:$H$2001,MATCH(1,('All Data'!$J$5:$J$2001=$A6)*('All Data'!$B$5:$B$2001=G$4)*('All Data'!$A$5:$A$2001=MAX(IF(('All Data'!$J$5:$J$2001=$A6)*('All Data'!$B$5:$B$2001=G$4),'All Data'!$A$5:$A$2001))),0)),"")) | H6: =IF(OR($A6="",H$4=""),"",IFERROR(INDEX('All Data'!$H$5:$H$2001,MATCH(1,('All Data'!$J$5:$J$2001=$A6)*('All Data'!$B$5:$B$2001=H$4)*('All Data'!$A$5:$A$2001=MAX(IF(('All Data'!$J$5:$J$2001=$A6)*('All Data'!$B$5:$B$2001=H$4),'All Data'!$A$5:$A$2001))),0)),"")) | I6: =IF(OR($A6="",I$4=""),"",IFERROR(INDEX('All Data'!$H$5:$H$2001,MATCH(1,('All Data'!$J$5:$J$2001=$A6)*('All Data'!$B$5:$B$2001=I$4)*('All Data'!$A$5:$A$2001=MAX(IF(('All Data'!$J$5:$J$2001=$A6)*('All Data'!$B$5:$B$2001=I$4),'All Data'!$A$5:$A$2001))),0)),"")) | J6: =IFERROR(MIN(D6,E6,F6,G6,H6,I6),"") | K6: =IFERROR(MAX(D6,E6,F6,G6,H6,I6),"") | L6: =IF(OR(J6="",K6=""),"",K6-J6) | M6: =IFERROR(INDEX($D$4:$I$4,MATCH(J6,$D6:$I6,0)),"")
A7: ='Item List'!A7 | B7: ='Item List'!B7 | C7: ='Item List'!C7 | D7: =IF(OR($A7="",D$4=""),"",IFERROR(INDEX('All Data'!$H$5:$H$2001,MATCH(1,('All Data'!$J$5:$J$2001=$A7)*('All Data'!$B$5:$B$2001=D$4)*('All Data'!$A$5:$A$2001=MAX(IF(('All Data'!$J$5:$J$2001=$A7)*('All Data'!$B$5:$B$2001=D$4),'All Data'!$A$5:$A$2001))),0)),"")) | E7: =IF(OR($A7="",E$4=""),"",IFERROR(INDEX('All Data'!$H$5:$H$2001,MATCH(1,('All Data'!$J$5:$J$2001=$A7)*('All Data'!$B$5:$B$2001=E$4)*('All Data'!$A$5:$A$2001=MAX(IF(('All Data'!$J$5:$J$2001=$A7)*('All Data'!$B$5:$B$2001=E$4),'All Data'!$A$5:$A$2001))),0)),"")) | F7: =IF(OR($A7="",F$4=""),"",IFERROR(INDEX('All Data'!$H$5:$H$2001,MATCH(1,('All Data'!$J$5:$J$2001=$A7)*('All Data'!$B$5:$B$2001=F$4)*('All Data'!$A$5:$A$2001=MAX(IF(('All Data'!$J$5:$J$2001=$A7)*('All Data'!$B$5:$B$2001=F$4),'All Data'!$A$5:$A$2001))),0)),"")) | G7: =IF(OR($A7="",G$4=""),"",IFERROR(INDEX('All Data'!$H$5:$H$2001,MATCH(1,('All Data'!$J$5:$J$2001=$A7)*('All Data'!$B$5:$B$2001=G$4)*('All Data'!$A$5:$A$2001=MAX(IF(('All Data'!$J$5:$J$2001=$A7)*('All Data'!$B$5:$B$2001=G$4),'All Data'!$A$5:$A$2001))),0)),"")) | H7: =IF(OR($A7="",H$4=""),"",IFERROR(INDEX('All Data'!$H$5:$H$2001,MATCH(1,('All Data'!$J$5:$J$2001=$A7)*('All Data'!$B$5:$B$2001=H$4)*('All Data'!$A$5:$A$2001=MAX(IF(('All Data'!$J$5:$J$2001=$A7)*('All Data'!$B$5:$B$2001=H$4),'All Data'!$A$5:$A$2001))),0)),"")) | I7: =IF(OR($A7="",I$4=""),"",IFERROR(INDEX('All Data'!$H$5:$H$2001,MATCH(1,('All Data'!$J$5:$J$2001=$A7)*('All Data'!$B$5:$B$2001=I$4)*('All Data'!$A$5:$A$2001=MAX(IF(('All Data'!$J$5:$J$2001=$A7)*('All Data'!$B$5:$B$2001=I$4),'All Data'!$A$5:$A$2001))),0)),"")) | J7: =IFERROR(MIN(D7,E7,F7,G7,H7,I7),"") | K7: =IFERROR(MAX(D7,E7,F7,G7,H7,I7),"") | L7: =IF(OR(J7="",K7=""),"",K7-J7) | M7: =IFERROR(INDEX($D$4:$I$4,MATCH(J7,$D7:$I7,0)),"")
A8: ='Item List'!A8 | B8: ='Item List'!B8 | C8: ='Item List'!C8 | D8: =IF(OR($A8="",D$4=""),"",IFERROR(INDEX('All Data'!$H$5:$H$2001,MATCH(1,('All Data'!$J$5:$J$2001=$A8)*('All Data'!$B$5:$B$2001=D$4)*('All Data'!$A$5:$A$2001=MAX(IF(('All Data'!$J$5:$J$2001=$A8)*('All Data'!$B$5:$B$2001=D$4),'All Data'!$A$5:$A$2001))),0)),"")) | E8: =IF(OR($A8="",E$4=""),"",IFERROR(INDEX('All Data'!$H$5:$H$2001,MATCH(1,('All Data'!$J$5:$J$2001=$A8)*('All Data'!$B$5:$B$2001=E$4)*('All Data'!$A$5:$A$2001=MAX(IF(('All Data'!$J$5:$J$2001=$A8)*('All Data'!$B$5:$B$2001=E$4),'All Data'!$A$5:$A$2001))),0)),"")) | F8: =IF(OR($A8="",F$4=""),"",IFERROR(INDEX('All Data'!$H$5:$H$2001,MATCH(1,('All Data'!$J$5:$J$2001=$A8)*('All Data'!$B$5:$B$2001=F$4)*('All Data'!$A$5:$A$2001=MAX(IF(('All Data'!$J$5:$J$2001=$A8)*('All Data'!$B$5:$B$2001=F$4),'All Data'!$A$5:$A$2001))),0)),"")) | G8: =IF(OR($A8="",G$4=""),"",IFERROR(INDEX('All Data'!$H$5:$H$2001,MATCH(1,('All Data'!$J$5:$J$2001=$A8)*('All Data'!$B$5:$B$2001=G$4)*('All Data'!$A$5:$A$2001=MAX(IF(('All Data'!$J$5:$J$2001=$A8)*('All Data'!$B$5:$B$2001=G$4),'All Data'!$A$5:$A$2001))),0)),"")) | H8: =IF(OR($A8="",H$4=""),"",IFERROR(INDEX('All Data'!$H$5:$H$2001,MATCH(1,('All Data'!$J$5:$J$2001=$A8)*('All Data'!$B$5:$B$2001=H$4)*('All Data'!$A$5:$A$2001=MAX(IF(('All Data'!$J$5:$J$2001=$A8)*('All Data'!$B$5:$B$2001=H$4),'All Data'!$A$5:$A$2001))),0)),"")) | I8: =IF(OR($A8="",I$4=""),"",IFERROR(INDEX('All Data'!$H$5:$H$2001,MATCH(1,('All Data'!$J$5:$J$2001=$A8)*('All Data'!$B$5:$B$2001=I$4)*('All Data'!$A$5:$A$2001=MAX(IF(('All Data'!$J$5:$J$2001=$A8)*('All Data'!$B$5:$B$2001=I$4),'All Data'!$A$5:$A$2001))),0)),"")) | J8: =IFERROR(MIN(D8,E8,F8,G8,H8,I8),"") | K8: =IFERROR(MAX(D8,E8,F8,G8,H8,I8),"") | L8: =IF(OR(J8="",K8=""),"",K8-J8) | M8: =IFERROR(INDEX($D$4:$I$4,MATCH(J8,$D8:$I8,0)),"")
A9: ='Item List'!A9 | B9: ='Item List'!B9 | C9: ='Item List'!C9 | D9: =IF(OR($A9="",D$4=""),"",IFERROR(INDEX('All Data'!$H$5:$H$2001,MATCH(1,('All Data'!$J$5:$J$2001=$A9)*('All Data'!$B$5:$B$2001=D$4)*('All Data'!$A$5:$A$2001=MAX(IF(('All Data'!$J$5:$J$2001=$A9)*('All Data'!$B$5:$B$2001=D$4),'All Data'!$A$5:$A$2001))),0)),"")) | E9: =IF(OR($A9="",E$4=""),"",IFERROR(INDEX('All Data'!$H$5:$H$2001,MATCH(1,('All Data'!$J$5:$J$2001=$A9)*('All Data'!$B$5:$B$2001=E$4)*('All Data'!$A$5:$A$2001=MAX(IF(('All Data'!$J$5:$J$2001=$A9)*('All Data'!$B$5:$B$2001=E$4),'All Data'!$A$5:$A$2001))),0)),"")) | F9: =IF(OR($A9="",F$4=""),"",IFERROR(INDEX('All Data'!$H$5:$H$2001,MATCH(1,('All Data'!$J$5:$J$2001=$A9)*('All Data'!$B$5:$B$2001=F$4)*('All Data'!$A$5:$A$2001=MAX(IF(('All Data'!$J$5:$J$2001=$A9)*('All Data'!$B$5:$B$2001=F$4),'All Data'!$A$5:$A$2001))),0)),"")) | G9: =IF(OR($A9="",G$4=""),"",IFERROR(INDEX('All Data'!$H$5:$H$2001,MATCH(1,('All Data'!$J$5:$J$2001=$A9)*('All Data'!$B$5:$B$2001=G$4)*('All Data'!$A$5:$A$2001=MAX(IF(('All Data'!$J$5:$J$2001=$A9)*('All Data'!$B$5:$B$2001=G$4),'All Data'!$A$5:$A$2001))),0)),"")) | H9: =IF(OR($A9="",H$4=""),"",IFERROR(INDEX('All Data'!$H$5:$H$2001,MATCH(1,('All Data'!$J$5:$J$2001=$A9)*('All Data'!$B$5:$B$2001=H$4)*('All Data'!$A$5:$A$2001=MAX(IF(('All Data'!$J$5:$J$2001=$A9)*('All Data'!$B$5:$B$2001=H$4),'All Data'!$A$5:$A$2001))),0)),"")) | I9: =IF(OR($A9="",I$4=""),"",IFERROR(INDEX('All Data'!$H$5:$H$2001,MATCH(1,('All Data'!$J$5:$J$2001=$A9)*('All Data'!$B$5:$B$2001=I$4)*('All Data'!$A$5:$A$2001=MAX(IF(('All Data'!$J$5:$J$2001=$A9)*('All Data'!$B$5:$B$2001=I$4),'All Data'!$A$5:$A$2001))),0)),"")) | J9: =IFERROR(MIN(D9,E9,F9,G9,H9,I9),"") | K9: =IFERROR(MAX(D9,E9,F9,G9,H9,I9),"") | L9: =IF(OR(J9="",K9=""),"",K9-J9) | M9: =IFERROR(INDEX($D$4:$I$4,MATCH(J9,$D9:$I9,0)),"")
A10: ='Item List'!A10 | B10: ='Item List'!B10 | C10: ='Item List'!C10 | D10: =IF(OR($A10="",D$4=""),"",IFERROR(INDEX('All Data'!$H$5:$H$2001,MATCH(1,('All Data'!$J$5:$J$2001=$A10)*('All Data'!$B$5:$B$2001=D$4)*('All Data'!$A$5:$A$2001=MAX(IF(('All Data'!$J$5:$J$2001=$A10)*('All Data'!$B$5:$B$2001=D$4),'All Data'!$A$5:$A$2001))),0)),"")) | E10: =IF(OR($A10="",E$4=""),"",IFERROR(INDEX('All Data'!$H$5:$H$2001,MATCH(1,('All Data'!$J$5:$J$2001=$A10)*('All Data'!$B$5:$B$2001=E$4)*('All Data'!$A$5:$A$2001=MAX(IF(('All Data'!$J$5:$J$2001=$A10)*('All Data'!$B$5:$B$2001=E$4),'All Data'!$A$5:$A$2001))),0)),"")) | F10: =IF(OR($A10="",F$4=""),"",IFERROR(INDEX('All Data'!$H$5:$H$2001,MATCH(1,('All Data'!$J$5:$J$2001=$A10)*('All Data'!$B$5:$B$2001=F$4)*('All Data'!$A$5:$A$2001=MAX(IF(('All Data'!$J$5:$J$2001=$A10)*('All Data'!$B$5:$B$2001=F$4),'All Data'!$A$5:$A$2001))),0)),"")) | G10: =IF(OR($A10="",G$4=""),"",IFERROR(INDEX('All Data'!$H$5:$H$2001,MATCH(1,('All Data'!$J$5:$J$2001=$A10)*('All Data'!$B$5:$B$2001=G$4)*('All Data'!$A$5:$A$2001=MAX(IF(('All Data'!$J$5:$J$2001=$A10)*('All Data'!$B$5:$B$2001=G$4),'All Data'!$A$5:$A$2001))),0)),"")) | H10: =IF(OR($A10="",H$4=""),"",IFERROR(INDEX('All Data'!$H$5:$H$2001,MATCH(1,('All Data'!$J$5:$J$2001=$A10)*('All Data'!$B$5:$B$2001=H$4)*('All Data'!$A$5:$A$2001=MAX(IF(('All Data'!$J$5:$J$2001=$A10)*('All Data'!$B$5:$B$2001=H$4),'All Data'!$A$5:$A$2001))),0)),"")) | I10: =IF(OR($A10="",I$4=""),"",IFERROR(INDEX('All Data'!$H$5:$H$2001,MATCH(1,('All Data'!$J$5:$J$2001=$A10)*('All Data'!$B$5:$B$2001=I$4)*('All Data'!$A$5:$A$2001=MAX(IF(('All Data'!$J$5:$J$2001=$A10)*('All Data'!$B$5:$B$2001=I$4),'All Data'!$A$5:$A$2001))),0)),"")) | J10: =IFERROR(MIN(D10,E10,F10,G10,H10,I10),"") | K10: =IFERROR(MAX(D10,E10,F10,G10,H10,I10),"") | L10: =IF(OR(J10="",K10=""),"",K10-J10) | M10: =IFERROR(INDEX($D$4:$I$4,MATCH(J10,$D10:$I10,0)),"")
A11: ='Item List'!A11 | B11: ='Item List'!B11 | C11: ='Item List'!C11 | D11: =IF(OR($A11="",D$4=""),"",IFERROR(INDEX('All Data'!$H$5:$H$2001,MATCH(1,('All Data'!$J$5:$J$2001=$A11)*('All Data'!$B$5:$B$2001=D$4)*('All Data'!$A$5:$A$2001=MAX(IF(('All Data'!$J$5:$J$2001=$A11)*('All Data'!$B$5:$B$2001=D$4),'All Data'!$A$5:$A$2001))),0)),"")) | E11: =IF(OR($A11="",E$4=""),"",IFERROR(INDEX('All Data'!$H$5:$H$2001,MATCH(1,('All Data'!$J$5:$J$2001=$A11)*('All Data'!$B$5:$B$2001=E$4)*('All Data'!$A$5:$A$2001=MAX(IF(('All Data'!$J$5:$J$2001=$A11)*('All Data'!$B$5:$B$2001=E$4),'All Data'!$A$5:$A$2001))),0)),"")) | F11: =IF(OR($A11="",F$4=""),"",IFERROR(INDEX('All Data'!$H$5:$H$2001,MATCH(1,('All Data'!$J$5:$J$2001=$A11)*('All Data'!$B$5:$B$2001=F$4)*('All Data'!$A$5:$A$2001=MAX(IF(('All Data'!$J$5:$J$2001=$A11)*('All Data'!$B$5:$B$2001=F$4),'All Data'!$A$5:$A$2001))),0)),"")) | G11: =IF(OR($A11="",G$4=""),"",IFERROR(INDEX('All Data'!$H$5:$H$2001,MATCH(1,('All Data'!$J$5:$J$2001=$A11)*('All Data'!$B$5:$B$2001=G$4)*('All Data'!$A$5:$A$2001=MAX(IF(('All Data'!$J$5:$J$2001=$A11)*('All Data'!$B$5:$B$2001=G$4),'All Data'!$A$5:$A$2001))),0)),"")) | H11: =IF(OR($A11="",H$4=""),"",IFERROR(INDEX('All Data'!$H$5:$H$2001,MATCH(1,('All Data'!$J$5:$J$2001=$A11)*('All Data'!$B$5:$B$2001=H$4)*('All Data'!$A$5:$A$2001=MAX(IF(('All Data'!$J$5:$J$2001=$A11)*('All Data'!$B$5:$B$2001=H$4),'All Data'!$A$5:$A$2001))),0)),"")) | I11: =IF(OR($A11="",I$4=""),"",IFERROR(INDEX('All Data'!$H$5:$H$2001,MATCH(1,('All Data'!$J$5:$J$2001=$A11)*('All Data'!$B$5:$B$2001=I$4)*('All Data'!$A$5:$A$2001=MAX(IF(('All Data'!$J$5:$J$2001=$A11)*('All Data'!$B$5:$B$2001=I$4),'All Data'!$A$5:$A$2001))),0)),"")) | J11: =IFERROR(MIN(D11,E11,F11,G11,H11,I11),"") | K11: =IFERROR(MAX(D11,E11,F11,G11,H11,I11),"") | L11: =IF(OR(J11="",K11=""),"",K11-J11) | M11: =IFERROR(INDEX($D$4:$I$4,MATCH(J11,$D11:$I11,0)),"")
A12: ='Item List'!A12 | B12: ='Item List'!B12 | C12: ='Item List'!C12 | D12: =IF(OR($A12="",D$4=""),"",IFERROR(INDEX('All Data'!$H$5:$H$2001,MATCH(1,('All Data'!$J$5:$J$2001=$A12)*('All Data'!$B$5:$B$2001=D$4)*('All Data'!$A$5:$A$2001=MAX(IF(('All Data'!$J$5:$J$2001=$A12)*('All Data'!$B$5:$B$2001=D$4),'All Data'!$A$5:$A$2001))),0)),"")) | E12: =IF(OR($A12="",E$4=""),"",IFERROR(INDEX('All Data'!$H$5:$H$2001,MATCH(1,('All Data'!$J$5:$J$2001=$A12)*('All Data'!$B$5:$B$2001=E$4)*('All Data'!$A$5:$A$2001=MAX(IF(('All Data'!$J$5:$J$2001=$A12)*('All Data'!$B$5:$B$2001=E$4),'All Data'!$A$5:$A$2001))),0)),"")) | F12: =IF(OR($A12="",F$4=""),"",IFERROR(INDEX('All Data'!$H$5:$H$2001,MATCH(1,('All Data'!$J$5:$J$2001=$A12)*('All Data'!$B$5:$B$2001=F$4)*('All Data'!$A$5:$A$2001=MAX(IF(('All Data'!$J$5:$J$2001=$A12)*('All Data'!$B$5:$B$2001=F$4),'All Data'!$A$5:$A$2001))),0)),"")) | G12: =IF(OR($A12="",G$4=""),"",IFERROR(INDEX('All Data'!$H$5:$H$2001,MATCH(1,('All Data'!$J$5:$J$2001=$A12)*('All Data'!$B$5:$B$2001=G$4)*('All Data'!$A$5:$A$2001=MAX(IF(('All Data'!$J$5:$J$2001=$A12)*('All Data'!$B$5:$B$2001=G$4),'All Data'!$A$5:$A$2001))),0)),"")) | H12: =IF(OR($A12="",H$4=""),"",IFERROR(INDEX('All Data'!$H$5:$H$2001,MATCH(1,('All Data'!$J$5:$J$2001=$A12)*('All Data'!$B$5:$B$2001=H$4)*('All Data'!$A$5:$A$2001=MAX(IF(('All Data'!$J$5:$J$2001=$A12)*('All Data'!$B$5:$B$2001=H$4),'All Data'!$A$5:$A$2001))),0)),"")) | I12: =IF(OR($A12="",I$4=""),"",IFERROR(INDEX('All Data'!$H$5:$H$2001,MATCH(1,('All Data'!$J$5:$J$2001=$A12)*('All Data'!$B$5:$B$2001=I$4)*('All Data'!$A$5:$A$2001=MAX(IF(('All Data'!$J$5:$J$2001=$A12)*('All Data'!$B$5:$B$2001=I$4),'All Data'!$A$5:$A$2001))),0)),"")) | J12: =IFERROR(MIN(D12,E12,F12,G12,H12,I12),"") | K12: =IFERROR(MAX(D12,E12,F12,G12,H12,I12),"") | L12: =IF(OR(J12="",K12=""),"",K12-J12) | M12: =IFERROR(INDEX($D$4:$I$4,MATCH(J12,$D12:$I12,0)),"")
A13: ='Item List'!A13 | B13: ='Item List'!B13 | C13: ='Item List'!C13 | D13: =IF(OR($A13="",D$4=""),"",IFERROR(INDEX('All Data'!$H$5:$H$2001,MATCH(1,('All Data'!$J$5:$J$2001=$A13)*('All Data'!$B$5:$B$2001=D$4)*('All Data'!$A$5:$A$2001=MAX(IF(('All Data'!$J$5:$J$2001=$A13)*('All Data'!$B$5:$B$2001=D$4),'All Data'!$A$5:$A$2001))),0)),"")) | E13: =IF(OR($A13="",E$4=""),"",IFERROR(INDEX('All Data'!$H$5:$H$2001,MATCH(1,('All Data'!$J$5:$J$2001=$A13)*('All Data'!$B$5:$B$2001=E$4)*('All Data'!$A$5:$A$2001=MAX(IF(('All Data'!$J$5:$J$2001=$A13)*('All Data'!$B$5:$B$2001=E$4),'All Data'!$A$5:$A$2001))),0)),"")) | F13: =IF(OR($A13="",F$4=""),"",IFERROR(INDEX('All Data'!$H$5:$H$2001,MATCH(1,('All Data'!$J$5:$J$2001=$A13)*('All Data'!$B$5:$B$2001=F$4)*('All Data'!$A$5:$A$2001=MAX(IF(('All Data'!$J$5:$J$2001=$A13)*('All Data'!$B$5:$B$2001=F$4),'All Data'!$A$5:$A$2001))),0)),"")) | G13: =IF(OR($A13="",G$4=""),"",IFERROR(INDEX('All Data'!$H$5:$H$2001,MATCH(1,('All Data'!$J$5:$J$2001=$A13)*('All Data'!$B$5:$B$2001=G$4)*('All Data'!$A$5:$A$2001=MAX(IF(('All Data'!$J$5:$J$2001=$A13)*('All Data'!$B$5:$B$2001=G$4),'All Data'!$A$5:$A$2001))),0)),"")) | H13: =IF(OR($A13="",H$4=""),"",IFERROR(INDEX('All Data'!$H$5:$H$2001,MATCH(1,('All Data'!$J$5:$J$2001=$A13)*('All Data'!$B$5:$B$2001=H$4)*('All Data'!$A$5:$A$2001=MAX(IF(('All Data'!$J$5:$J$2001=$A13)*('All Data'!$B$5:$B$2001=H$4),'All Data'!$A$5:$A$2001))),0)),"")) | I13: =IF(OR($A13="",I$4=""),"",IFERROR(INDEX('All Data'!$H$5:$H$2001,MATCH(1,('All Data'!$J$5:$J$2001=$A13)*('All Data'!$B$5:$B$2001=I$4)*('All Data'!$A$5:$A$2001=MAX(IF(('All Data'!$J$5:$J$2001=$A13)*('All Data'!$B$5:$B$2001=I$4),'All Data'!$A$5:$A$2001))),0)),"")) | J13: =IFERROR(MIN(D13,E13,F13,G13,H13,I13),"") | K13: =IFERROR(MAX(D13,E13,F13,G13,H13,I13),"") | L13: =IF(OR(J13="",K13=""),"",K13-J13) | M13: =IFERROR(INDEX($D$4:$I$4,MATCH(J13,$D13:$I13,0)),"")
A14: ='Item List'!A14 | B14: ='Item List'!B14 | C14: ='Item List'!C14 | D14: =IF(OR($A14="",D$4=""),"",IFERROR(INDEX('All Data'!$H$5:$H$2001,MATCH(1,('All Data'!$J$5:$J$2001=$A14)*('All Data'!$B$5:$B$2001=D$4)*('All Data'!$A$5:$A$2001=MAX(IF(('All Data'!$J$5:$J$2001=$A14)*('All Data'!$B$5:$B$2001=D$4),'All Data'!$A$5:$A$2001))),0)),"")) | E14: =IF(OR($A14="",E$4=""),"",IFERROR(INDEX('All Data'!$H$5:$H$2001,MATCH(1,('All Data'!$J$5:$J$2001=$A14)*('All Data'!$B$5:$B$2001=E$4)*('All Data'!$A$5:$A$2001=MAX(IF(('All Data'!$J$5:$J$2001=$A14)*('All Data'!$B$5:$B$2001=E$4),'All Data'!$A$5:$A$2001))),0)),"")) | F14: =IF(OR($A14="",F$4=""),"",IFERROR(INDEX('All Data'!$H$5:$H$2001,MATCH(1,('All Data'!$J$5:$J$2001=$A14)*('All Data'!$B$5:$B$2001=F$4)*('All Data'!$A$5:$A$2001=MAX(IF(('All Data'!$J$5:$J$2001=$A14)*('All Data'!$B$5:$B$2001=F$4),'All Data'!$A$5:$A$2001))),0)),"")) | G14: =IF(OR($A14="",G$4=""),"",IFERROR(INDEX('All Data'!$H$5:$H$2001,MATCH(1,('All Data'!$J$5:$J$2001=$A14)*('All Data'!$B$5:$B$2001=G$4)*('All Data'!$A$5:$A$2001=MAX(IF(('All Data'!$J$5:$J$2001=$A14)*('All Data'!$B$5:$B$2001=G$4),'All Data'!$A$5:$A$2001))),0)),"")) | H14: =IF(OR($A14="",H$4=""),"",IFERROR(INDEX('All Data'!$H$5:$H$2001,MATCH(1,('All Data'!$J$5:$J$2001=$A14)*('All Data'!$B$5:$B$2001=H$4)*('All Data'!$A$5:$A$2001=MAX(IF(('All Data'!$J$5:$J$2001=$A14)*('All Data'!$B$5:$B$2001=H$4),'All Data'!$A$5:$A$2001))),0)),"")) | I14: =IF(OR($A14="",I$4=""),"",IFERROR(INDEX('All Data'!$H$5:$H$2001,MATCH(1,('All Data'!$J$5:$J$2001=$A14)*('All Data'!$B$5:$B$2001=I$4)*('All Data'!$A$5:$A$2001=MAX(IF(('All Data'!$J$5:$J$2001=$A14)*('All Data'!$B$5:$B$2001=I$4),'All Data'!$A$5:$A$2001))),0)),"")) | J14: =IFERROR(MIN(D14,E14,F14,G14,H14,I14),"") | K14: =IFERROR(MAX(D14,E14,F14,G14,H14,I14),"") | L14: =IF(OR(J14="",K14=""),"",K14-J14) | M14: =IFERROR(INDEX($D$4:$I$4,MATCH(J14,$D14:$I14,0)),"")
A15: ='Item List'!A15 | B15: ='Item List'!B15 | C15: ='Item List'!C15 | D15: =IF(OR($A15="",D$4=""),"",IFERROR(INDEX('All Data'!$H$5:$H$2001,MATCH(1,('All Data'!$J$5:$J$2001=$A15)*('All Data'!$B$5:$B$2001=D$4)*('All Data'!$A$5:$A$2001=MAX(IF(('All Data'!$J$5:$J$2001=$A15)*('All Data'!$B$5:$B$2001=D$4),'All Data'!$A$5:$A$2001))),0)),"")) | E15: =IF(OR($A15="",E$4=""),"",IFERROR(INDEX('All Data'!$H$5:$H$2001,MATCH(1,('All Data'!$J$5:$J$2001=$A15)*('All Data'!$B$5:$B$2001=E$4)*('All Data'!$A$5:$A$2001=MAX(IF(('All Data'!$J$5:$J$2001=$A15)*('All Data'!$B$5:$B$2001=E$4),'All Data'!$A$5:$A$2001))),0)),"")) | F15: =IF(OR($A15="",F$4=""),"",IFERROR(INDEX('All Data'!$H$5:$H$2001,MATCH(1,('All Data'!$J$5:$J$2001=$A15)*('All Data'!$B$5:$B$2001=F$4)*('All Data'!$A$5:$A$2001=MAX(IF(('All Data'!$J$5:$J$2001=$A15)*('All Data'!$B$5:$B$2001=F$4),'All Data'!$A$5:$A$2001))),0)),"")) | G15: =IF(OR($A15="",G$4=""),"",IFERROR(INDEX('All Data'!$H$5:$H$2001,MATCH(1,('All Data'!$J$5:$J$2001=$A15)*('All Data'!$B$5:$B$2001=G$4)*('All Data'!$A$5:$A$2001=MAX(IF(('All Data'!$J$5:$J$2001=$A15)*('All Data'!$B$5:$B$2001=G$4),'All Data'!$A$5:$A$2001))),0)),"")) | H15: =IF(OR($A15="",H$4=""),"",IFERROR(INDEX('All Data'!$H$5:$H$2001,MATCH(1,('All Data'!$J$5:$J$2001=$A15)*('All Data'!$B$5:$B$2001=H$4)*('All Data'!$A$5:$A$2001=MAX(IF(('All Data'!$J$5:$J$2001=$A15)*('All Data'!$B$5:$B$2001=H$4),'All Data'!$A$5:$A$2001))),0)),"")) | I15: =IF(OR($A15="",I$4=""),"",IFERROR(INDEX('All Data'!$H$5:$H$2001,MATCH(1,('All Data'!$J$5:$J$2001=$A15)*('All Data'!$B$5:$B$2001=I$4)*('All Data'!$A$5:$A$2001=MAX(IF(('All Data'!$J$5:$J$2001=$A15)*('All Data'!$B$5:$B$2001=I$4),'All Data'!$A$5:$A$2001))),0)),"")) | J15: =IFERROR(MIN(D15,E15,F15,G15,H15,I15),"") | K15: =IFERROR(MAX(D15,E15,F15,G15,H15,I15),"") | L15: =IF(OR(J15="",K15=""),"",K15-J15) | M15: =IFERROR(INDEX($D$4:$I$4,MATCH(J15,$D15:$I15,0)),"")
A16: ='Item List'!A16 | B16: ='Item List'!B16 | C16: ='Item List'!C16 | D16: =IF(OR($A16="",D$4=""),"",IFERROR(INDEX('All Data'!$H$5:$H$2001,MATCH(1,('All Data'!$J$5:$J$2001=$A16)*('All Data'!$B$5:$B$2001=D$4)*('All Data'!$A$5:$A$2001=MAX(IF(('All Data'!$J$5:$J$2001=$A16)*('All Data'!$B$5:$B$2001=D$4),'All Data'!$A$5:$A$2001))),0)),"")) | E16: =IF(OR($A16="",E$4=""),"",IFERROR(INDEX('All Data'!$H$5:$H$2001,MATCH(1,('All Data'!$J$5:$J$2001=$A16)*('All Data'!$B$5:$B$2001=E$4)*('All Data'!$A$5:$A$2001=MAX(IF(('All Data'!$J$5:$J$2001=$A16)*('All Data'!$B$5:$B$2001=E$4),'All Data'!$A$5:$A$2001))),0)),"")) | F16: =IF(OR($A16="",F$4=""),"",IFERROR(INDEX('All Data'!$H$5:$H$2001,MATCH(1,('All Data'!$J$5:$J$2001=$A16)*('All Data'!$B$5:$B$2001=F$4)*('All Data'!$A$5:$A$2001=MAX(IF(('All Data'!$J$5:$J$2001=$A16)*('All Data'!$B$5:$B$2001=F$4),'All Data'!$A$5:$A$2001))),0)),"")) | G16: =IF(OR($A16="",G$4=""),"",IFERROR(INDEX('All Data'!$H$5:$H$2001,MATCH(1,('All Data'!$J$5:$J$2001=$A16)*('All Data'!$B$5:$B$2001=G$4)*('All Data'!$A$5:$A$2001=MAX(IF(('All Data'!$J$5:$J$2001=$A16)*('All Data'!$B$5:$B$2001=G$4),'All Data'!$A$5:$A$2001))),0)),"")) | H16: =IF(OR($A16="",H$4=""),"",IFERROR(INDEX('All Data'!$H$5:$H$2001,MATCH(1,('All Data'!$J$5:$J$2001=$A16)*('All Data'!$B$5:$B$2001=H$4)*('All Data'!$A$5:$A$2001=MAX(IF(('All Data'!$J$5:$J$2001=$A16)*('All Data'!$B$5:$B$2001=H$4),'All Data'!$A$5:$A$2001))),0)),"")) | I16: =IF(OR($A16="",I$4=""),"",IFERROR(INDEX('All Data'!$H$5:$H$2001,MATCH(1,('All Data'!$J$5:$J$2001=$A16)*('All Data'!$B$5:$B$2001=I$4)*('All Data'!$A$5:$A$2001=MAX(IF(('All Data'!$J$5:$J$2001=$A16)*('All Data'!$B$5:$B$2001=I$4),'All Data'!$A$5:$A$2001))),0)),"")) | J16: =IFERROR(MIN(D16,E16,F16,G16,H16,I16),"") | K16: =IFERROR(MAX(D16,E16,F16,G16,H16,I16),"") | L16: =IF(OR(J16="",K16=""),"",K16-J16) | M16: =IFERROR(INDEX($D$4:$I$4,MATCH(J16,$D16:$I16,0)),"")
... A45: ='Item List'!A45 | B45: ='Item List'!B45 | C45: ='Item List'!C45 | D45: =IF(OR($A45="",D$4=""),"",IFERROR(INDEX('All Data'!$H$5:$H$2001,MATCH(1,('All Data'!$J$5:$J$2001=$A45)*('All Data'!$B$5:$B$2001=D$4)*('All Data'!$A$5:$A$2001=MAX(IF(('All Data'!$J$5:$J$2001=$A45)*('All Data'!$B$5:$B$2001=D$4),'All Data'!$A$5:$A$2001))),0)),"")) | E45: =IF(OR($A45="",E$4=""),"",IFERROR(INDEX('All Data'!$H$5:$H$2001,MATCH(1,('All Data'!$J$5:$J$2001=$A45)*('All Data'!$B$5:$B$2001=E$4)*('All Data'!$A$5:$A$2001=MAX(IF(('All Data'!$J$5:$J$2001=$A45)*('All Data'!$B$5:$B$2001=E$4),'All Data'!$A$5:$A$2001))),0)),"")) | F45: =IF(OR($A45="",F$4=""),"",IFERROR(INDEX('All Data'!$H$5:$H$2001,MATCH(1,('All Data'!$J$5:$J$2001=$A45)*('All Data'!$B$5:$B$2001=F$4)*('All Data'!$A$5:$A$2001=MAX(IF(('All Data'!$J$5:$J$2001=$A45)*('All Data'!$B$5:$B$2001=F$4),'All Data'!$A$5:$A$2001))),0)),"")) | G45: =IF(OR($A45="",G$4=""),"",IFERROR(INDEX('All Data'!$H$5:$H$2001,MATCH(1,('All Data'!$J$5:$J$2001=$A45)*('All Data'!$B$5:$B$2001=G$4)*('All Data'!$A$5:$A$2001=MAX(IF(('All Data'!$J$5:$J$2001=$A45)*('All Data'!$B$5:$B$2001=G$4),'All Data'!$A$5:$A$2001))),0)),"")) | H45: =IF(OR($A45="",H$4=""),"",IFERROR(INDEX('All Data'!$H$5:$H$2001,MATCH(1,('All Data'!$J$5:$J$2001=$A45)*('All Data'!$B$5:$B$2001=H$4)*('All Data'!$A$5:$A$2001=MAX(IF(('All Data'!$J$5:$J$2001=$A45)*('All Data'!$B$5:$B$2001=H$4),'All Data'!$A$5:$A$2001))),0)),"")) | I45: =IF(OR($A45="",I$4=""),"",IFERROR(INDEX('All Data'!$H$5:$H$2001,MATCH(1,('All Data'!$J$5:$J$2001=$A45)*('All Data'!$B$5:$B$2001=I$4)*('All Data'!$A$5:$A$2001=MAX(IF(('All Data'!$J$5:$J$2001=$A45)*('All Data'!$B$5:$B$2001=I$4),'All Data'!$A$5:$A$2001))),0)),"")) | J45: =IFERROR(MIN(D45,E45,F45,G45,H45,I45),"") | K45: =IFERROR(MAX(D45,E45,F45,G45,H45,I45),"") | L45: =IF(OR(J45="",K45=""),"",K45-J45) | M45: =IFERROR(INDEX($D$4:$I$4,MATCH(J45,$D45:$I45,0)),"")

Sheet All Data
A1: All Data - full history with price-change analysis
A2: Auto-generated from 'Data Entry'. Don't type here - everything is a formula. 'Flag' shows when a price went UP compared to the last time you bought that same item at that same location.
A4: Date | B4: Location | C4: Supplier | D4: Item Code | E4: Item Name | F4: Unit | G4: Qty | H4: Unit Price ($) | I4: Amount ($) | J4: Item Key | K4: Prev Price ($) | L4: Change ($) | M4: Change (%) | N4: Flag
A5: =IF('Data Entry'!A5="","",'Data Entry'!A5) | B5: =IF('Data Entry'!A5="","",'Data Entry'!B5) | C5: =IF('Data Entry'!A5="","",'Data Entry'!C5) | D5: =IF('Data Entry'!A5="","",'Data Entry'!D5) | E5: =IF('Data Entry'!A5="","",'Data Entry'!E5) | F5: =IF('Data Entry'!A5="","",'Data Entry'!F5) | G5: =IF('Data Entry'!A5="","",'Data Entry'!G5) | H5: =IF('Data Entry'!A5="","",'Data Entry'!H5) | I5: =IF('Data Entry'!A5="","",'Data Entry'!I5) | J5: =IF('Data Entry'!A5="","",IF('Data Entry'!D5<>"",'Data Entry'!D5,'Data Entry'!E5)) | K5: =IF('Data Entry'!A5="","",IFERROR(SUMIFS($H$5:$H$2001,$J$5:$J$2001,$J5,$B$5:$B$2001,$B5,$A$5:$A$2001,(MAXIFS($A$5:$A$2001,$J$5:$J$2001,$J5,$B$5:$B$2001,$B5,$A$5:$A$2001,"<"&$A5))),"")) | L5: =IF(OR('Data Entry'!A5="",$K5=""),"",$H5-$K5) | M5: =IF(OR('Data Entry'!A5="",$K5="",$K5=0),"",$L5/$K5) | N5: =IF('Data Entry'!A5="","",IF($L5="","New item",IF($L5>0,"UP",IF($L5<0,"down","same"))))
